<?xml version="1.0"?>
<robot xmlns:xacro="http://www.ros.org/wiki/xacro" >

    <xacro:include filename="inertial_macros.xacro"/>


    <xacro:property name="chassis_length" value="0.6096"/>
    <xacro:property name="chassis_width" value="0.55885"/>
    <xacro:property name="chassis_height" value="0.05715"/>
    <xacro:property name="chassis_mass" value="1.0"/>
    <xacro:property name="wheel_radius" value="0.05"/>
    <xacro:property name="wheel_thickness" value="0.05"/>
    <xacro:property name="wheel_mass" value="0.1"/>
    <xacro:property name="wheel_offset_x" value="0"/>
    <xacro:property name="wheel_offset_y" value="0.1485"/>
    <xacro:property name="wheel_offset_z" value="0"/>
   
    <material name="white">
        <color rgba="1 1 1 1" />
    </material>

    <material name="orange">
        <color rgba="1 0.3 0.1 1"/>
    </material>

    <material name="blue">
        <color rgba="0.2 0.2 1 1"/>
    </material>

    <material name="black">
        <color rgba="0 0 0 1"/>
    </material>

    <material name="red">
        <color rgba="1 0 0 1"/>
    </material>

    <!-- BASE LINK -->

    <link name="base_link">

    </link>

    <!-- BASE_FOOTPRINT LINK -->
    <joint name="base_footprint_joint" type="fixed">
        <parent link="base_link"/>
        <child link="base_footprint"/>
        <origin xyz="0 0 0" rpy="0 0 0"/>
    </joint>
    


    <link name="base_footprint">
    </link>
    


    <!-- CHASSIS LINK -->

    <joint name="chassis_joint" type="fixed">
        <parent link="base_link"/>
        <child link="chassis"/>
        <origin xyz="0 0 0"/>
    </joint>

    <link name="chassis">
        <visual>
            <origin xyz="0 0 0" rpy="0 0 0"/>
            <geometry>
                <box size="${chassis_length} ${chassis_width} ${chassis_height}"/>
            </geometry>
            <material name="orange"/>
        </visual>
        <collision>
            <origin xyz="0 0 0"/>
            <geometry>
                <box size="${chassis_length} ${chassis_width} ${chassis_height}"/>
            </geometry>
        </collision>
        <xacro:inertial_box mass="0.5" x="${chassis_length}" y="${chassis_width}" z="${chassis_height}">
            <origin xyz="0 0 0" rpy="0 0 0"/>
        </xacro:inertial_box>
    </link>

    <gazebo reference="chassis">
        <material>Gazebo/Orange</material>
    </gazebo>

    <!-- LEFT WHEEL FRONT LINK -->

    <joint name="left_front_joint" type="continuous">
        <parent link="base_link"/>
        <child link="left_front"/>
        <origin xyz="0.2032 0.3000 0" rpy="-${pi/2} 0 0" />
        <axis xyz="0 0 1"/>
    </joint>

    <link name="left_front">
        <visual>
            <geometry>
                <cylinder radius="0.05" length="0.04"/>
            </geometry>
            <material name="blue"/>
        </visual>
        <collision>
            <geometry>
                <sphere radius="${wheel_radius}"/>
            </geometry>
        </collision>
        <xacro:inertial_cylinder mass="${wheel_mass}" length="${wheel_thickness}" radius="${wheel_radius}">
            <origin xyz="0 0 0" rpy="0 0 0"/>
        </xacro:inertial_cylinder>
    </link>

    <gazebo reference="left_front">
        <material>Gazebo/Blue</material>
        <mu1 value="0.001"/>
        <mu2 value="0.001"/>
    </gazebo>


<!-- LEFT WHEEL CENTER LINK -->

    <joint name="left_center_joint" type="continuous">
        <parent link="base_link"/>
        <child link="left_center"/>
        <origin xyz="0 0.3000 0" rpy="-${pi/2} 0 0" />
        <axis xyz="0 0 1"/>
    </joint>

    <link name="left_center">
        <visual>
            <geometry>
                <cylinder radius="${wheel_radius}" length="0.04"/>
            </geometry>
            <material name="blue"/>
        </visual>
        <collision>
            <geometry>
                <sphere radius="${wheel_radius}"/>
            </geometry>
        </collision>
        <xacro:inertial_cylinder mass="${wheel_mass}" length="${wheel_thickness}" radius="${wheel_radius}">
            <origin xyz="0 0 0" rpy="0 0 0"/>
        </xacro:inertial_cylinder>
    </link>

    <gazebo reference="left_center">
        <material>Gazebo/Blue</material>
    </gazebo>

<!-- LEFT WHEEL BACK LINK -->

    <joint name="left_back_joint" type="continuous">
        <parent link="base_link"/>
        <child link="left_back"/>
        <origin xyz="-0.2032 0.3000 0" rpy="-${pi/2} 0 0" />
        <axis xyz="0 0 1"/>
    </joint>

    <link name="left_back">
        <visual>
            <geometry>
                <cylinder radius="${wheel_radius}" length="0.04"/>
            </geometry>
            <material name="blue"/>
        </visual>
        <collision>
            <geometry>
                <sphere radius="${wheel_radius}"/>
            </geometry>
        </collision>
        <xacro:inertial_cylinder mass="${wheel_mass}" length="${wheel_thickness}" radius="${wheel_radius}">
            <origin xyz="0 0 0" rpy="0 0 0"/>
        </xacro:inertial_cylinder>
    </link>

    <gazebo reference="left_back">
        <material>Gazebo/Blue</material>
        <mu1 value="0.001"/>
        <mu2 value="0.001"/>
    </gazebo>


    <!-- RIGHT WHEEL FRONT LINK -->

    <joint name="right_front_joint" type="continuous">
        <parent link="base_link"/>
        <child link="right_front"/>
        <origin xyz="0.2032 -0.3000 0" rpy="${pi/2} 0 0" />
        <axis xyz="0 0 1"/>
    </joint>

    <link name="right_front">
        <visual>
            <geometry>
                <cylinder radius="${wheel_radius}" length="0.04"/>
            </geometry>
            <material name="blue"/>
        </visual>
        <collision>
            <geometry>
                <sphere radius="${wheel_radius}"/>
            </geometry>
        </collision>
        <xacro:inertial_cylinder mass="${wheel_mass}" length="${wheel_thickness}" radius="${wheel_radius}">
            <origin xyz="0 0 0" rpy="0 0 0"/>
        </xacro:inertial_cylinder>
    </link>

    <gazebo reference="right_front">
        <material>Gazebo/Blue</material>
        <mu1 value="0.001"/>
        <mu2 value="0.001"/>
    </gazebo>


    <!-- RIGHT WHEEL CENTER LINK -->

    <joint name="right_center_joint" type="continuous">
        <parent link="base_link"/>
        <child link="right_center"/>
        <origin xyz="0 -0.3000 0" rpy="${pi/2} 0 0" />
        <axis xyz="0 0 -1"/>
    </joint>

    <link name="right_center">
        <visual>
            <geometry>
                <cylinder radius="${wheel_radius}" length="0.04"/>
            </geometry>
            <material name="blue"/>
        </visual>
        <collision>
            <geometry>
                <sphere radius="${wheel_radius}"/>
            </geometry>
        </collision>
        <xacro:inertial_cylinder mass="${wheel_mass}" length="${wheel_thickness}" radius="${wheel_radius}">
            <origin xyz="0 0 0" rpy="0 0 0"/>
        </xacro:inertial_cylinder>
    </link>

    <gazebo reference="right_center">
        <material>Gazebo/Blue</material>
    </gazebo>


        <!-- RIGHT WHEEL BACK LINK -->

    <joint name="right_back_joint" type="continuous">
        <parent link="base_link"/>
        <child link="right_back"/>
        <origin xyz="-0.2032 -0.3000 0" rpy="${pi/2} 0 0" />
        <axis xyz="0 0 -1"/>
    </joint>

    <link name="right_back">
        <visual>
            <geometry>
                <cylinder radius="${wheel_radius}" length="0.04"/>
            </geometry>
            <material name="blue"/>
        </visual>
        <collision>
            <geometry>
                <sphere radius="${wheel_radius}"/>
            </geometry>
        </collision>
        <xacro:inertial_cylinder mass="${wheel_mass}" length="${wheel_thickness}" radius="${wheel_radius}">
            <origin xyz="0 0 0" rpy="0 0 0"/>
        </xacro:inertial_cylinder>
    </link>

    <gazebo reference="right_back">
        <material>Gazebo/Blue</material>
        <mu1 value="0.001"/>
        <mu2 value="0.001"/>
    </gazebo>



</robot>